[0062b408] pulse audio output error: PulseAudio server connection failure: Connection refused
[01f00eb8] pulse audio output error: PulseAudio server connection failure: Connection refused
[01a783f8] pulse audio output error: PulseAudio server connection failure: Connection refused
[01df18a8] pulse audio output error: PulseAudio server connection failure: Connection refused
[02033928] pulse audio output error: PulseAudio server connection failure: Connection refused
[01e93538] pulse audio output error: PulseAudio server connection failure: Connection refused
[01df3fd8] pulse audio output error: PulseAudio server connection failure: Connection refused
[0237fbe8] pulse audio output error: PulseAudio server connection failure: Connection refused
[010d5c30] pulse audio output error: PulseAudio server connection failure: Connection refused
[00b6bc10] pulse audio output error: PulseAudio server connection failure: Connection refused
python3: can't open file 'faceDetection.py': [Errno 2] No such file or directory
python3: can't open file 'faceDetection.py': [Errno 2] No such file or directory
python3: can't open file 'faceDetection.py': [Errno 2] No such file or directory
python3: can't open file 'faceDetection.py': [Errno 2] No such file or directory
python3: can't open file 'faceDetection.py': [Errno 2] No such file or directory
python3: can't open file 'faceDetection.py': [Errno 2] No such file or directory
python3: can't open file 'faceDetection.py': [Errno 2] No such file or directory
python3: can't open file 'faceDetection.py': [Errno 2] No such file or directory
python3: can't open file 'faceDetection.py': [Errno 2] No such file or directory
python3: can't open file 'faceDetection.py': [Errno 2] No such file or directory
python3: can't open file 'faceDetection.py': [Errno 2] No such file or directory
python3: can't open file 'faceDetection.py': [Errno 2] No such file or directory
python3: can't open file 'faceDetection.py': [Errno 2] No such file or directory
python3: can't open file 'faceDetection.py': [Errno 2] No such file or directory
python3: can't open file 'faceDetection.py': [Errno 2] No such file or directory
python3: can't open file 'faceDetection.py': [Errno 2] No such file or directory
python3: can't open file 'faceDetection.py': [Errno 2] No such file or directory
python3: can't open file 'faceDetection.py': [Errno 2] No such file or directory
python3: can't open file 'faceDetection.py': [Errno 2] No such file or directory
python3: can't open file 'faceDetection.py': [Errno 2] No such file or directory
python3: can't open file 'faceDetection.py': [Errno 2] No such file or directory
python3: can't open file 'faceDetection.py': [Errno 2] No such file or directory
python3: can't open file 'faceDetection.py': [Errno 2] No such file or directory
python3: can't open file 'faceDetection.py': [Errno 2] No such file or directory
python3: can't open file 'faceDetection.py': [Errno 2] No such file or directory
python3: can't open file 'faceDetection.py': [Errno 2] No such file or directory
python3: can't open file 'faceDetection.py': [Errno 2] No such file or directory
[0237fbe8] alsa audio output error: cannot estimate delay: Broken pipe
python3: can't open file 'faceDetection.py': [Errno 2] No such file or directory
python3: can't open file 'faceDetection.py': [Errno 2] No such file or directory
[0238e120] core input error: ES_OUT_SET_(GROUP_)PCR  is called too late (pts_delay increased to 300 ms)
[0238e120] core input error: ES_OUT_RESET_PCR called
[0237fbe8] alsa audio output error: cannot estimate delay: Broken pipe
python3: can't open file 'faceDetection.py': [Errno 2] No such file or directory
python3: can't open file 'faceDetection.py': [Errno 2] No such file or directory
python3: can't open file 'faceDetection.py': [Errno 2] No such file or directory
python3: can't open file 'faceDetection.py': [Errno 2] No such file or directory
python3: can't open file 'faceDetection.py': [Errno 2] No such file or directory
python3: can't open file 'faceDetection.py': [Errno 2] No such file or directory
python3: can't open file 'faceDetection.py': [Errno 2] No such file or directory
python3: can't open file 'faceDetection.py': [Errno 2] No such file or directory
python3: can't open file 'faceDetection.py': [Errno 2] No such file or directory
python3: can't open file 'faceDetection.py': [Errno 2] No such file or directory
python3: can't open file 'faceDetection.py': [Errno 2] No such file or directory
python3: can't open file 'faceDetection.py': [Errno 2] No such file or directory
python3: can't open file 'faceDetection.py': [Errno 2] No such file or directory
python3: can't open file 'faceDetection.py': [Errno 2] No such file or directory
python3: can't open file 'faceDetection.py': [Errno 2] No such file or directory
python3: can't open file 'faceDetection.py': [Errno 2] No such file or directory
python3: can't open file 'faceDetection.py': [Errno 2] No such file or directory
python3: can't open file 'faceDetection.py': [Errno 2] No such file or directory
python3: can't open file 'faceDetection.py': [Errno 2] No such file or directory
python3: can't open file 'faceDetection.py': [Errno 2] No such file or directory
python3: can't open file 'faceDetection.py': [Errno 2] No such file or directory
python3: can't open file 'faceDetection.py': [Errno 2] No such file or directory
python3: can't open file 'faceDetection.py': [Errno 2] No such file or directory
python3: can't open file 'faceDetection.py': [Errno 2] No such file or directory
python3: can't open file 'faceDetection.py': [Errno 2] No such file or directory
python3: can't open file 'faceDetection.py': [Errno 2] No such file or directory
python3: can't open file 'faceDetection.py': [Errno 2] No such file or directory
python3: can't open file 'faceDetection.py': [Errno 2] No such file or directory
python3: can't open file 'faceDetection.py': [Errno 2] No such file or directory
python3: can't open file 'faceDetection.py': [Errno 2] No such file or directory
python3: can't open file 'faceDetection.py': [Errno 2] No such file or directory
[01d282f8] pulse audio output error: PulseAudio server connection failure: Connection refused
Traceback (most recent call last):
  File "mqttRpi.py", line 41, in <module>
    clientEV3.connect("10.42.0.54", 1883, 60000)
  File "/usr/local/lib/python3.5/dist-packages/paho/mqtt/client.py", line 768, in connect
    return self.reconnect()
  File "/usr/local/lib/python3.5/dist-packages/paho/mqtt/client.py", line 895, in reconnect
    sock = socket.create_connection((self._host, self._port), source_address=(self._bind_address, 0))
  File "/usr/lib/python3.5/socket.py", line 712, in create_connection
    raise err
  File "/usr/lib/python3.5/socket.py", line 703, in create_connection
    sock.connect(sa)
OSError: [Errno 113] No route to host
